Traceback (most recent call last):
  File "/root/anaconda3/lib/python3.9/site-packages/django/core/management/base.py", line 412, in run_from_argv
    self.execute(*args, **cmd_options)
  File "/root/anaconda3/lib/python3.9/site-packages/django/core/management/commands/runserver.py", line 74, in execute
    super().execute(*args, **options)
  File "/root/anaconda3/lib/python3.9/site-packages/django/core/management/base.py", line 458, in execute
    output = self.handle(*args, **options)
  File "/root/anaconda3/lib/python3.9/site-packages/django/core/management/commands/runserver.py", line 81, in handle
    if not settings.DEBUG and not settings.ALLOWED_HOSTS:
  File "/root/anaconda3/lib/python3.9/site-packages/django/conf/__init__.py", line 102, in __getattr__
    self._setup(name)
  File "/root/anaconda3/lib/python3.9/site-packages/django/conf/__init__.py", line 89, in _setup
    self._wrapped = Settings(settings_module)
  File "/root/anaconda3/lib/python3.9/site-packages/django/conf/__init__.py", line 217, in __init__
    mod = importlib.import_module(self.SETTINGS_MODULE)
  File "/root/anaconda3/lib/python3.9/importlib/__init__.py", line 127, in import_module
    return _bootstrap._gcd_import(name[level:], package, level)
  File "<frozen importlib._bootstrap>", line 1030, in _gcd_import
  File "<frozen importlib._bootstrap>", line 1007, in _find_and_load
  File "<frozen importlib._bootstrap>", line 986, in _find_and_load_unlocked
  File "<frozen importlib._bootstrap>", line 680, in _load_unlocked
  File "<frozen importlib._bootstrap_external>", line 850, in exec_module
  File "<frozen importlib._bootstrap>", line 228, in _call_with_frames_removed
  File "/root/PWA/avatar_colab/settings.py", line 15, in <module>
    from cv2 import MEDIA_FORMAT_BGR
ImportError: libGL.so.1: cannot open shared object file: No such file or directory

During handling of the above exception, another exception occurred:

Traceback (most recent call last):
  File "/root/PWA/manage.py", line 22, in <module>
    main()
  File "/root/PWA/manage.py", line 18, in main
    execute_from_command_line(sys.argv)
  File "/root/anaconda3/lib/python3.9/site-packages/django/core/management/__init__.py", line 442, in execute_from_command_line
    utility.execute()
  File "/root/anaconda3/lib/python3.9/site-packages/django/core/management/__init__.py", line 436, in execute
    self.fetch_command(subcommand).run_from_argv(self.argv)
  File "/root/anaconda3/lib/python3.9/site-packages/django/core/management/base.py", line 425, in run_from_argv
    connections.close_all()
  File "/root/anaconda3/lib/python3.9/site-packages/django/utils/connection.py", line 84, in close_all
    for conn in self.all(initialized_only=True):
  File "/root/anaconda3/lib/python3.9/site-packages/django/utils/connection.py", line 76, in all
    return [
  File "/root/anaconda3/lib/python3.9/site-packages/django/utils/connection.py", line 73, in __iter__
    return iter(self.settings)
  File "/root/anaconda3/lib/python3.9/site-packages/django/utils/functional.py", line 57, in __get__
    res = instance.__dict__[self.name] = self.func(instance)
  File "/root/anaconda3/lib/python3.9/site-packages/django/utils/connection.py", line 45, in settings
    self._settings = self.configure_settings(self._settings)
  File "/root/anaconda3/lib/python3.9/site-packages/django/db/utils.py", line 148, in configure_settings
    databases = super().configure_settings(databases)
  File "/root/anaconda3/lib/python3.9/site-packages/django/utils/connection.py", line 50, in configure_settings
    settings = getattr(django_settings, self.settings_name)
  File "/root/anaconda3/lib/python3.9/site-packages/django/conf/__init__.py", line 102, in __getattr__
    self._setup(name)
  File "/root/anaconda3/lib/python3.9/site-packages/django/conf/__init__.py", line 89, in _setup
    self._wrapped = Settings(settings_module)
  File "/root/anaconda3/lib/python3.9/site-packages/django/conf/__init__.py", line 217, in __init__
    mod = importlib.import_module(self.SETTINGS_MODULE)
  File "/root/anaconda3/lib/python3.9/importlib/__init__.py", line 127, in import_module
    return _bootstrap._gcd_import(name[level:], package, level)
  File "<frozen importlib._bootstrap>", line 1030, in _gcd_import
  File "<frozen importlib._bootstrap>", line 1007, in _find_and_load
  File "<frozen importlib._bootstrap>", line 986, in _find_and_load_unlocked
  File "<frozen importlib._bootstrap>", line 680, in _load_unlocked
  File "<frozen importlib._bootstrap_external>", line 850, in exec_module
  File "<frozen importlib._bootstrap>", line 228, in _call_with_frames_removed
  File "/root/PWA/avatar_colab/settings.py", line 15, in <module>
    from cv2 import MEDIA_FORMAT_BGR
ImportError: libGL.so.1: cannot open shared object file: No such file or directory
Traceback (most recent call last):
  File "/root/anaconda3/lib/python3.9/site-packages/django/core/management/base.py", line 412, in run_from_argv
    self.execute(*args, **cmd_options)
  File "/root/anaconda3/lib/python3.9/site-packages/django/core/management/commands/runserver.py", line 74, in execute
    super().execute(*args, **options)
  File "/root/anaconda3/lib/python3.9/site-packages/django/core/management/base.py", line 458, in execute
    output = self.handle(*args, **options)
  File "/root/anaconda3/lib/python3.9/site-packages/django/core/management/commands/runserver.py", line 81, in handle
    if not settings.DEBUG and not settings.ALLOWED_HOSTS:
  File "/root/anaconda3/lib/python3.9/site-packages/django/conf/__init__.py", line 102, in __getattr__
    self._setup(name)
  File "/root/anaconda3/lib/python3.9/site-packages/django/conf/__init__.py", line 89, in _setup
    self._wrapped = Settings(settings_module)
  File "/root/anaconda3/lib/python3.9/site-packages/django/conf/__init__.py", line 217, in __init__
    mod = importlib.import_module(self.SETTINGS_MODULE)
  File "/root/anaconda3/lib/python3.9/importlib/__init__.py", line 127, in import_module
    return _bootstrap._gcd_import(name[level:], package, level)
  File "<frozen importlib._bootstrap>", line 1030, in _gcd_import
  File "<frozen importlib._bootstrap>", line 1007, in _find_and_load
  File "<frozen importlib._bootstrap>", line 986, in _find_and_load_unlocked
  File "<frozen importlib._bootstrap>", line 680, in _load_unlocked
  File "<frozen importlib._bootstrap_external>", line 850, in exec_module
  File "<frozen importlib._bootstrap>", line 228, in _call_with_frames_removed
  File "/root/PWA/avatar_colab/settings.py", line 15, in <module>
    from cv2 import MEDIA_FORMAT_BGR
ImportError: libGL.so.1: cannot open shared object file: No such file or directory

During handling of the above exception, another exception occurred:

Traceback (most recent call last):
  File "/root/PWA/manage.py", line 22, in <module>
    main()
  File "/root/PWA/manage.py", line 18, in main
    execute_from_command_line(sys.argv)
  File "/root/anaconda3/lib/python3.9/site-packages/django/core/management/__init__.py", line 442, in execute_from_command_line
    utility.execute()
  File "/root/anaconda3/lib/python3.9/site-packages/django/core/management/__init__.py", line 436, in execute
    self.fetch_command(subcommand).run_from_argv(self.argv)
  File "/root/anaconda3/lib/python3.9/site-packages/django/core/management/base.py", line 425, in run_from_argv
    connections.close_all()
  File "/root/anaconda3/lib/python3.9/site-packages/django/utils/connection.py", line 84, in close_all
    for conn in self.all(initialized_only=True):
  File "/root/anaconda3/lib/python3.9/site-packages/django/utils/connection.py", line 76, in all
    return [
  File "/root/anaconda3/lib/python3.9/site-packages/django/utils/connection.py", line 73, in __iter__
    return iter(self.settings)
  File "/root/anaconda3/lib/python3.9/site-packages/django/utils/functional.py", line 57, in __get__
    res = instance.__dict__[self.name] = self.func(instance)
  File "/root/anaconda3/lib/python3.9/site-packages/django/utils/connection.py", line 45, in settings
    self._settings = self.configure_settings(self._settings)
  File "/root/anaconda3/lib/python3.9/site-packages/django/db/utils.py", line 148, in configure_settings
    databases = super().configure_settings(databases)
  File "/root/anaconda3/lib/python3.9/site-packages/django/utils/connection.py", line 50, in configure_settings
    settings = getattr(django_settings, self.settings_name)
  File "/root/anaconda3/lib/python3.9/site-packages/django/conf/__init__.py", line 102, in __getattr__
    self._setup(name)
  File "/root/anaconda3/lib/python3.9/site-packages/django/conf/__init__.py", line 89, in _setup
    self._wrapped = Settings(settings_module)
  File "/root/anaconda3/lib/python3.9/site-packages/django/conf/__init__.py", line 217, in __init__
    mod = importlib.import_module(self.SETTINGS_MODULE)
  File "/root/anaconda3/lib/python3.9/importlib/__init__.py", line 127, in import_module
    return _bootstrap._gcd_import(name[level:], package, level)
  File "<frozen importlib._bootstrap>", line 1030, in _gcd_import
  File "<frozen importlib._bootstrap>", line 1007, in _find_and_load
  File "<frozen importlib._bootstrap>", line 986, in _find_and_load_unlocked
  File "<frozen importlib._bootstrap>", line 680, in _load_unlocked
  File "<frozen importlib._bootstrap_external>", line 850, in exec_module
  File "<frozen importlib._bootstrap>", line 228, in _call_with_frames_removed
  File "/root/PWA/avatar_colab/settings.py", line 15, in <module>
    from cv2 import MEDIA_FORMAT_BGR
ImportError: libGL.so.1: cannot open shared object file: No such file or directory
Watching for file changes with StatReloader
Performing system checks...

/root/anaconda3/lib/python3.9/site-packages/numba/np/ufunc/parallel.py:371: NumbaWarning: The TBB threading layer requires TBB version 2021 update 6 or later i.e., TBB_INTERFACE_VERSION >= 12060. Found TBB_INTERFACE_VERSION = 12040. The TBB threading layer is disabled.
  warnings.warn(problem)
System check identified no issues (0 silenced).
Exception in thread django-main-thread:
Traceback (most recent call last):
  File "/root/anaconda3/lib/python3.9/site-packages/django/db/backends/base/base.py", line 289, in ensure_connection
    self.connect()
  File "/root/anaconda3/lib/python3.9/site-packages/django/utils/asyncio.py", line 26, in inner
    return func(*args, **kwargs)
  File "/root/anaconda3/lib/python3.9/site-packages/django/db/backends/base/base.py", line 270, in connect
    self.connection = self.get_new_connection(conn_params)
  File "/root/anaconda3/lib/python3.9/site-packages/django/utils/asyncio.py", line 26, in inner
    return func(*args, **kwargs)
  File "/root/anaconda3/lib/python3.9/site-packages/django/db/backends/postgresql/base.py", line 275, in get_new_connection
    connection = self.Database.connect(**conn_params)
  File "/root/anaconda3/lib/python3.9/site-packages/psycopg2/__init__.py", line 122, in connect
    conn = _connect(dsn, connection_factory=connection_factory, **kwasync)
psycopg2.OperationalError: connection to server at "aws-0-eu-central-1.pooler.supabase.com" (18.198.145.223), port 5432  failed: FATAL:  Authentication error, reason: "Authentication query failed: %DBConnection.ConnectionError{message: \"connection not available and request was dropped from queue after 10000ms. This means requests are coming in and your connection pool cannot serve them fast enough. You can address this by:\\n\\n  1. Ensuring your database is available and that you can connect to it\\n  2. Tracking down slow queries and making sure they are running fast enough\\n  3. Increasing the pool_size (although this increases resource consumption)\\n  4. Allowing requests to wait longer by increasing :queue_target and :queue_interval\\n\\nSee DBConnection.start_link/2 for more information\\n\", severity: :error, reason: :queue_timeout}"
connection to server at "aws-0-eu-central-1.pooler.supabase.com" (18.198.145.223), port 5432  failed: FATAL:  Authentication error, reason: "Authentication query failed: %DBConnection.ConnectionError{message: \"connection not available and request was dropped from queue after 10000ms. This means requests are coming in and your connection pool cannot serve them fast enough. You can address this by:\\n\\n  1. Ensuring your database is available and that you can connect to it\\n  2. Tracking down slow queries and making sure they are running fast enough\\n  3. Increasing the pool_size (although this increases resource consumption)\\n  4. Allowing requests to wait longer by increasing :queue_target and :queue_interval\\n\\nSee DBConnection.start_link/2 for more information\\n\", severity: :error, reason: :queue_timeout}"


The above exception was the direct cause of the following exception:

Traceback (most recent call last):
  File "/root/anaconda3/lib/python3.9/threading.py", line 973, in _bootstrap_inner
    self.run()
  File "/root/anaconda3/lib/python3.9/threading.py", line 910, in run
    self._target(*self._args, **self._kwargs)
  File "/root/anaconda3/lib/python3.9/site-packages/django/utils/autoreload.py", line 64, in wrapper
    fn(*args, **kwargs)
  File "/root/anaconda3/lib/python3.9/site-packages/django/core/management/commands/runserver.py", line 136, in inner_run
    self.check_migrations()
  File "/root/anaconda3/lib/python3.9/site-packages/django/core/management/base.py", line 574, in check_migrations
    executor = MigrationExecutor(connections[DEFAULT_DB_ALIAS])
  File "/root/anaconda3/lib/python3.9/site-packages/django/db/migrations/executor.py", line 18, in __init__
    self.loader = MigrationLoader(self.connection)
  File "/root/anaconda3/lib/python3.9/site-packages/django/db/migrations/loader.py", line 58, in __init__
    self.build_graph()
  File "/root/anaconda3/lib/python3.9/site-packages/django/db/migrations/loader.py", line 235, in build_graph
    self.applied_migrations = recorder.applied_migrations()
  File "/root/anaconda3/lib/python3.9/site-packages/django/db/migrations/recorder.py", line 81, in applied_migrations
    if self.has_table():
  File "/root/anaconda3/lib/python3.9/site-packages/django/db/migrations/recorder.py", line 57, in has_table
    with self.connection.cursor() as cursor:
  File "/root/anaconda3/lib/python3.9/site-packages/django/utils/asyncio.py", line 26, in inner
    return func(*args, **kwargs)
  File "/root/anaconda3/lib/python3.9/site-packages/django/db/backends/base/base.py", line 330, in cursor
    return self._cursor()
  File "/root/anaconda3/lib/python3.9/site-packages/django/db/backends/base/base.py", line 306, in _cursor
    self.ensure_connection()
  File "/root/anaconda3/lib/python3.9/site-packages/django/utils/asyncio.py", line 26, in inner
    return func(*args, **kwargs)
  File "/root/anaconda3/lib/python3.9/site-packages/django/db/backends/base/base.py", line 289, in ensure_connection
    self.connect()
  File "/root/anaconda3/lib/python3.9/site-packages/django/db/utils.py", line 91, in __exit__
    raise dj_exc_value.with_traceback(traceback) from exc_value
  File "/root/anaconda3/lib/python3.9/site-packages/django/db/backends/base/base.py", line 289, in ensure_connection
    self.connect()
  File "/root/anaconda3/lib/python3.9/site-packages/django/utils/asyncio.py", line 26, in inner
    return func(*args, **kwargs)
  File "/root/anaconda3/lib/python3.9/site-packages/django/db/backends/base/base.py", line 270, in connect
    self.connection = self.get_new_connection(conn_params)
  File "/root/anaconda3/lib/python3.9/site-packages/django/utils/asyncio.py", line 26, in inner
    return func(*args, **kwargs)
  File "/root/anaconda3/lib/python3.9/site-packages/django/db/backends/postgresql/base.py", line 275, in get_new_connection
    connection = self.Database.connect(**conn_params)
  File "/root/anaconda3/lib/python3.9/site-packages/psycopg2/__init__.py", line 122, in connect
    conn = _connect(dsn, connection_factory=connection_factory, **kwasync)
django.db.utils.OperationalError: connection to server at "aws-0-eu-central-1.pooler.supabase.com" (18.198.145.223), port 5432  failed: FATAL:  Authentication error, reason: "Authentication query failed: %DBConnection.ConnectionError{message: \"connection not available and request was dropped from queue after 10000ms. This means requests are coming in and your connection pool cannot serve them fast enough. You can address this by:\\n\\n  1. Ensuring your database is available and that you can connect to it\\n  2. Tracking down slow queries and making sure they are running fast enough\\n  3. Increasing the pool_size (although this increases resource consumption)\\n  4. Allowing requests to wait longer by increasing :queue_target and :queue_interval\\n\\nSee DBConnection.start_link/2 for more information\\n\", severity: :error, reason: :queue_timeout}"
connection to server at "aws-0-eu-central-1.pooler.supabase.com" (18.198.145.223), port 5432  failed: FATAL:  Authentication error, reason: "Authentication query failed: %DBConnection.ConnectionError{message: \"connection not available and request was dropped from queue after 10000ms. This means requests are coming in and your connection pool cannot serve them fast enough. You can address this by:\\n\\n  1. Ensuring your database is available and that you can connect to it\\n  2. Tracking down slow queries and making sure they are running fast enough\\n  3. Increasing the pool_size (although this increases resource consumption)\\n  4. Allowing requests to wait longer by increasing :queue_target and :queue_interval\\n\\nSee DBConnection.start_link/2 for more information\\n\", severity: :error, reason: :queue_timeout}"

/root/PWA/avatar_colab/settings.py changed, reloading.
Watching for file changes with StatReloader
Performing system checks...

/root/anaconda3/lib/python3.9/site-packages/numba/np/ufunc/parallel.py:371: NumbaWarning: The TBB threading layer requires TBB version 2021 update 6 or later i.e., TBB_INTERFACE_VERSION >= 12060. Found TBB_INTERFACE_VERSION = 12040. The TBB threading layer is disabled.
  warnings.warn(problem)
System check identified no issues (0 silenced).
Exception in thread django-main-thread:
Traceback (most recent call last):
  File "/root/anaconda3/lib/python3.9/site-packages/django/db/backends/base/base.py", line 289, in ensure_connection
    self.connect()
  File "/root/anaconda3/lib/python3.9/site-packages/django/utils/asyncio.py", line 26, in inner
    return func(*args, **kwargs)
  File "/root/anaconda3/lib/python3.9/site-packages/django/db/backends/base/base.py", line 270, in connect
    self.connection = self.get_new_connection(conn_params)
  File "/root/anaconda3/lib/python3.9/site-packages/django/utils/asyncio.py", line 26, in inner
    return func(*args, **kwargs)
  File "/root/anaconda3/lib/python3.9/site-packages/django/db/backends/postgresql/base.py", line 275, in get_new_connection
    connection = self.Database.connect(**conn_params)
  File "/root/anaconda3/lib/python3.9/site-packages/psycopg2/__init__.py", line 122, in connect
    conn = _connect(dsn, connection_factory=connection_factory, **kwasync)
psycopg2.OperationalError: connection to server at "aws-0-eu-central-1.pooler.supabase.com" (18.198.30.239), port 5432  failed: FATAL:  Authentication error, reason: "Authentication query failed: %DBConnection.ConnectionError{message: \"connection not available and request was dropped from queue after 10000ms. This means requests are coming in and your connection pool cannot serve them fast enough. You can address this by:\\n\\n  1. Ensuring your database is available and that you can connect to it\\n  2. Tracking down slow queries and making sure they are running fast enough\\n  3. Increasing the pool_size (although this increases resource consumption)\\n  4. Allowing requests to wait longer by increasing :queue_target and :queue_interval\\n\\nSee DBConnection.start_link/2 for more information\\n\", severity: :error, reason: :queue_timeout}"
connection to server at "aws-0-eu-central-1.pooler.supabase.com" (18.198.30.239), port 5432  failed: FATAL:  Authentication error, reason: "Authentication query failed: %DBConnection.ConnectionError{message: \"connection not available and request was dropped from queue after 10000ms. This means requests are coming in and your connection pool cannot serve them fast enough. You can address this by:\\n\\n  1. Ensuring your database is available and that you can connect to it\\n  2. Tracking down slow queries and making sure they are running fast enough\\n  3. Increasing the pool_size (although this increases resource consumption)\\n  4. Allowing requests to wait longer by increasing :queue_target and :queue_interval\\n\\nSee DBConnection.start_link/2 for more information\\n\", severity: :error, reason: :queue_timeout}"


The above exception was the direct cause of the following exception:

Traceback (most recent call last):
  File "/root/anaconda3/lib/python3.9/threading.py", line 973, in _bootstrap_inner
    self.run()
  File "/root/anaconda3/lib/python3.9/threading.py", line 910, in run
    self._target(*self._args, **self._kwargs)
  File "/root/anaconda3/lib/python3.9/site-packages/django/utils/autoreload.py", line 64, in wrapper
    fn(*args, **kwargs)
  File "/root/anaconda3/lib/python3.9/site-packages/django/core/management/commands/runserver.py", line 136, in inner_run
    self.check_migrations()
  File "/root/anaconda3/lib/python3.9/site-packages/django/core/management/base.py", line 574, in check_migrations
    executor = MigrationExecutor(connections[DEFAULT_DB_ALIAS])
  File "/root/anaconda3/lib/python3.9/site-packages/django/db/migrations/executor.py", line 18, in __init__
    self.loader = MigrationLoader(self.connection)
  File "/root/anaconda3/lib/python3.9/site-packages/django/db/migrations/loader.py", line 58, in __init__
    self.build_graph()
  File "/root/anaconda3/lib/python3.9/site-packages/django/db/migrations/loader.py", line 235, in build_graph
    self.applied_migrations = recorder.applied_migrations()
  File "/root/anaconda3/lib/python3.9/site-packages/django/db/migrations/recorder.py", line 81, in applied_migrations
    if self.has_table():
  File "/root/anaconda3/lib/python3.9/site-packages/django/db/migrations/recorder.py", line 57, in has_table
    with self.connection.cursor() as cursor:
  File "/root/anaconda3/lib/python3.9/site-packages/django/utils/asyncio.py", line 26, in inner
    return func(*args, **kwargs)
  File "/root/anaconda3/lib/python3.9/site-packages/django/db/backends/base/base.py", line 330, in cursor
    return self._cursor()
  File "/root/anaconda3/lib/python3.9/site-packages/django/db/backends/base/base.py", line 306, in _cursor
    self.ensure_connection()
  File "/root/anaconda3/lib/python3.9/site-packages/django/utils/asyncio.py", line 26, in inner
    return func(*args, **kwargs)
  File "/root/anaconda3/lib/python3.9/site-packages/django/db/backends/base/base.py", line 289, in ensure_connection
    self.connect()
  File "/root/anaconda3/lib/python3.9/site-packages/django/db/utils.py", line 91, in __exit__
    raise dj_exc_value.with_traceback(traceback) from exc_value
  File "/root/anaconda3/lib/python3.9/site-packages/django/db/backends/base/base.py", line 289, in ensure_connection
    self.connect()
  File "/root/anaconda3/lib/python3.9/site-packages/django/utils/asyncio.py", line 26, in inner
    return func(*args, **kwargs)
  File "/root/anaconda3/lib/python3.9/site-packages/django/db/backends/base/base.py", line 270, in connect
    self.connection = self.get_new_connection(conn_params)
  File "/root/anaconda3/lib/python3.9/site-packages/django/utils/asyncio.py", line 26, in inner
    return func(*args, **kwargs)
  File "/root/anaconda3/lib/python3.9/site-packages/django/db/backends/postgresql/base.py", line 275, in get_new_connection
    connection = self.Database.connect(**conn_params)
  File "/root/anaconda3/lib/python3.9/site-packages/psycopg2/__init__.py", line 122, in connect
    conn = _connect(dsn, connection_factory=connection_factory, **kwasync)
django.db.utils.OperationalError: connection to server at "aws-0-eu-central-1.pooler.supabase.com" (18.198.30.239), port 5432  failed: FATAL:  Authentication error, reason: "Authentication query failed: %DBConnection.ConnectionError{message: \"connection not available and request was dropped from queue after 10000ms. This means requests are coming in and your connection pool cannot serve them fast enough. You can address this by:\\n\\n  1. Ensuring your database is available and that you can connect to it\\n  2. Tracking down slow queries and making sure they are running fast enough\\n  3. Increasing the pool_size (although this increases resource consumption)\\n  4. Allowing requests to wait longer by increasing :queue_target and :queue_interval\\n\\nSee DBConnection.start_link/2 for more information\\n\", severity: :error, reason: :queue_timeout}"
connection to server at "aws-0-eu-central-1.pooler.supabase.com" (18.198.30.239), port 5432  failed: FATAL:  Authentication error, reason: "Authentication query failed: %DBConnection.ConnectionError{message: \"connection not available and request was dropped from queue after 10000ms. This means requests are coming in and your connection pool cannot serve them fast enough. You can address this by:\\n\\n  1. Ensuring your database is available and that you can connect to it\\n  2. Tracking down slow queries and making sure they are running fast enough\\n  3. Increasing the pool_size (although this increases resource consumption)\\n  4. Allowing requests to wait longer by increasing :queue_target and :queue_interval\\n\\nSee DBConnection.start_link/2 for more information\\n\", severity: :error, reason: :queue_timeout}"

/root/PWA/avatar_colab/settings.py changed, reloading.
Watching for file changes with StatReloader
Performing system checks...

/root/anaconda3/lib/python3.9/site-packages/numba/np/ufunc/parallel.py:371: NumbaWarning: The TBB threading layer requires TBB version 2021 update 6 or later i.e., TBB_INTERFACE_VERSION >= 12060. Found TBB_INTERFACE_VERSION = 12040. The TBB threading layer is disabled.
  warnings.warn(problem)
System check identified no issues (0 silenced).

You have 5 unapplied migration(s). Your project may not work properly until you apply the migrations for app(s): account, core_app_root_avatar_creation.
Run 'python manage.py migrate' to apply them.
June 08, 2024 - 23:06:54
Django version 4.2.13, using settings 'avatar_colab.settings'
Starting development server at http://68.183.118.46:8000/
Quit the server with CONTROL-C.

Watching for file changes with StatReloader
Performing system checks...

/root/anaconda3/lib/python3.9/site-packages/numba/np/ufunc/parallel.py:371: NumbaWarning: The TBB threading layer requires TBB version 2021 update 6 or later i.e., TBB_INTERFACE_VERSION >= 12060. Found TBB_INTERFACE_VERSION = 12040. The TBB threading layer is disabled.
  warnings.warn(problem)
System check identified no issues (0 silenced).
Error: That port is already in use.
[08/Jun/2024 23:09:48] "GET /swagger/ HTTP/1.1" 200 2165
[08/Jun/2024 23:09:48] "GET /static/drf-yasg/style.css HTTP/1.1" 200 1047
[08/Jun/2024 23:09:49] "GET /static/drf-yasg/insQ.min.js HTTP/1.1" 200 2093
[08/Jun/2024 23:09:49] "GET /static/drf-yasg/swagger-ui-init.js HTTP/1.1" 200 14964
[08/Jun/2024 23:09:50] "GET /static/drf-yasg/immutable.min.js HTTP/1.1" 200 56904
[08/Jun/2024 23:09:50] "GET /static/drf-yasg/swagger-ui-dist/swagger-ui.css HTTP/1.1" 200 145206
[08/Jun/2024 23:09:51] "GET /static/drf-yasg/swagger-ui-dist/swagger-ui-standalone-preset.js HTTP/1.1" 200 322863
[08/Jun/2024 23:10:13] "GET /static/drf-yasg/swagger-ui-dist/swagger-ui-bundle.js HTTP/1.1" 200 1046583
[08/Jun/2024 23:10:18] "GET /swagger/?format=openapi HTTP/1.1" 200 2185
[08/Jun/2024 23:10:18] "GET /static/drf-yasg/swagger-ui-dist/favicon-32x32.png HTTP/1.1" 200 628
[08/Jun/2024 23:10:19] "GET /swagger/?format=openapi HTTP/1.1" 200 2185
Not Found: /
[09/Jun/2024 00:19:31] "GET / HTTP/1.1" 404 2831
Not Found: /
[09/Jun/2024 01:47:05] "GET / HTTP/1.1" 404 2831
Not Found: /favicon.ico
[09/Jun/2024 01:47:23] "GET /favicon.ico HTTP/1.1" 404 2882
Not Found: /http:/api.ipify.org/
[09/Jun/2024 01:47:27] "GET http://api.ipify.org/?format=json HTTP/1.1" 404 1818
Not Found: /www.shadowserver.org:443
[09/Jun/2024 01:47:30] "CONNECT www.shadowserver.org:443 HTTP/1.1" 404 1827
Not Found: /
[09/Jun/2024 06:03:36] "GET / HTTP/1.1" 404 2831
[09/Jun/2024 06:30:25] code 400, message Bad request version ('À\x14À')
[09/Jun/2024 06:30:25] You're accessing the development server over HTTPS, but it only supports HTTP.
[09/Jun/2024 06:30:26] code 400, message Bad request version ('À\x14À')
[09/Jun/2024 06:30:26] You're accessing the development server over HTTPS, but it only supports HTTP.
Not Found: /
[09/Jun/2024 06:30:26] "GET / HTTP/1.1" 404 2831
[09/Jun/2024 06:30:27] code 400, message Bad HTTP/0.9 request type ('\x16\x03\x01\x00{\x01\x00\x00w\x03\x03½äÍ\x80ì\xad%a\x9dV¿\x15Ä¼.²\x0f¤ÕHíû\x99\x92ãZ\x84¿à0\x05ª\x00\x00\x1aÀ/À+À\x11À\x07À\x13À')
[09/Jun/2024 06:30:27] You're accessing the development server over HTTPS, but it only supports HTTP.
Not Found: /login
[09/Jun/2024 06:30:28] "GET /login HTTP/1.1" 404 2864
[09/Jun/2024 06:51:30] code 400, message Bad request version ('À\x14À')
[09/Jun/2024 06:51:30] You're accessing the development server over HTTPS, but it only supports HTTP.
[09/Jun/2024 07:02:35] "GET /swagger/ HTTP/1.1" 200 2165
[09/Jun/2024 07:02:36] "GET /static/drf-yasg/swagger-ui-dist/swagger-ui.css HTTP/1.1" 304 0
[09/Jun/2024 07:02:36] "GET /static/drf-yasg/style.css HTTP/1.1" 304 0
[09/Jun/2024 07:02:36] "GET /static/drf-yasg/swagger-ui-dist/swagger-ui-bundle.js HTTP/1.1" 304 0
[09/Jun/2024 07:02:36] "GET /static/drf-yasg/insQ.min.js HTTP/1.1" 304 0
[09/Jun/2024 07:02:36] "GET /static/drf-yasg/swagger-ui-dist/swagger-ui-standalone-preset.js HTTP/1.1" 304 0
[09/Jun/2024 07:02:36] "GET /static/drf-yasg/immutable.min.js HTTP/1.1" 304 0
[09/Jun/2024 07:02:37] "GET /static/drf-yasg/swagger-ui-init.js HTTP/1.1" 304 0
[09/Jun/2024 07:02:38] "GET /swagger/?format=openapi HTTP/1.1" 200 2185
[09/Jun/2024 07:02:39] "GET /swagger/?format=openapi HTTP/1.1" 200 2185
/root/PWA/core_app_root/avatar_creation/viewsets/create_avatar.py changed, reloading.
Watching for file changes with StatReloader
Performing system checks...

/root/anaconda3/lib/python3.9/site-packages/numba/np/ufunc/parallel.py:371: NumbaWarning: The TBB threading layer requires TBB version 2021 update 6 or later i.e., TBB_INTERFACE_VERSION >= 12060. Found TBB_INTERFACE_VERSION = 12040. The TBB threading layer is disabled.
  warnings.warn(problem)
System check identified no issues (0 silenced).
June 09, 2024 - 07:03:56
Django version 4.2.13, using settings 'avatar_colab.settings'
Starting development server at http://68.183.118.46:8000/
Quit the server with CONTROL-C.

/root/PWA/core_app_root/avatar_creation/viewsets/create_avatar.py changed, reloading.
Watching for file changes with StatReloader
Performing system checks...

/root/anaconda3/lib/python3.9/site-packages/numba/np/ufunc/parallel.py:371: NumbaWarning: The TBB threading layer requires TBB version 2021 update 6 or later i.e., TBB_INTERFACE_VERSION >= 12060. Found TBB_INTERFACE_VERSION = 12040. The TBB threading layer is disabled.
  warnings.warn(problem)
System check identified no issues (0 silenced).
June 09, 2024 - 07:04:01
Django version 4.2.13, using settings 'avatar_colab.settings'
Starting development server at http://68.183.118.46:8000/
Quit the server with CONTROL-C.

/root/PWA/core_app_root/avatar_creation/viewsets/create_avatar.py changed, reloading.
Watching for file changes with StatReloader
Performing system checks...

/root/anaconda3/lib/python3.9/site-packages/numba/np/ufunc/parallel.py:371: NumbaWarning: The TBB threading layer requires TBB version 2021 update 6 or later i.e., TBB_INTERFACE_VERSION >= 12060. Found TBB_INTERFACE_VERSION = 12040. The TBB threading layer is disabled.
  warnings.warn(problem)
System check identified no issues (0 silenced).
June 09, 2024 - 07:04:05
Django version 4.2.13, using settings 'avatar_colab.settings'
Starting development server at http://68.183.118.46:8000/
Quit the server with CONTROL-C.

Not Found: /aaa9
[09/Jun/2024 09:36:52] "GET /aaa9 HTTP/1.1" 404 2861
Not Found: /aab8
[09/Jun/2024 09:36:52] "GET /aab8 HTTP/1.1" 404 2861
Not Found: /
[09/Jun/2024 09:36:52] "GET / HTTP/1.1" 404 2831
[09/Jun/2024 09:56:58] code 400, message Bad request syntax ('\x05\x01\x00')
[09/Jun/2024 09:56:58] " " 400 -
[09/Jun/2024 09:57:13] code 400, message Bad request syntax ('\x04\x01\x00P¬Ù\x18N\x00')
[09/Jun/2024 09:57:13] " P¬ÙN " 400 -
[09/Jun/2024 09:57:18] code 400, message Bad request syntax ('\x05\x01\x00')
[09/Jun/2024 09:57:18] " " 400 -
[09/Jun/2024 09:57:34] code 400, message Bad request syntax ('\x04\x01\x00P¬Ù\x1b\x0e\x00')
[09/Jun/2024 09:57:34] " P¬Ù " 400 -
[09/Jun/2024 10:39:04] code 400, message Bad request version ('À\x14À')
[09/Jun/2024 10:39:04] You're accessing the development server over HTTPS, but it only supports HTTP.
[09/Jun/2024 11:08:45,273] - Broken pipe from ('45.79.115.117', 35215)
Not Found: /
[09/Jun/2024 11:08:45] "GET / HTTP/1.1" 404 2826
[09/Jun/2024 11:08:45,496] - Broken pipe from ('45.79.115.117', 35216)
Not Found: /
[09/Jun/2024 11:08:57] "GET / HTTP/1.1" 404 2831
